Workbook

Sheet 전표_샘플
A1: 전표ID | B1: 기업ID | C1: 날짜 | D1: 거래처 | E1: 품목명 | F1: 공급가액 | G1: 부가세 | H1: 합계금액 | I1: 수량 | J1: 단위 | K1: 정답Scope | L1: 정답분류 | M1: 정답연료 | N1: 데이터품질 | O1: 혼합품목 | P1: 배분규칙 | Q1: 사람검토필요 | R1: 근거 | S1: 개발메모
A2: I001 | B2: C001 | C2: 45728 | D2: 구미에너지 | E2: 지게차 경유 외 1종 | F2: 654000 | G2: 65400 | H2: 719400 | I2: 500 | J2: L | K2: Scope 1 | L2: 이동연소 | M2: 경유 | N2: A | O2: TRUE | P2: 주품목 100% | Q2: FALSE | R2: 지게차+경유가 명시되어 직접배출 | S2: 명확 케이스
A3: I002 | B3: C001 | C3: 45736 | D3: 한국전력 | E3: 공장 전기요금 | F3: 1200000 | G3: 120000 | H3: 1320000 | I3: 3500 | J3: kWh | K3: Scope 2 | L3: 전력사용 | M3: 전기 | N3: A | O3: FALSE | P3: 해당없음 | Q3: FALSE | R3: 한전 전기요금은 Scope 2 | S3: 명확 케이스
A4: I003 | B4: C001 | C4: 45741 | D4: 대구문구 | E4: 사무용품 구입 | F4: 150000 | G4: 15000 | H4: 165000 | K4: 제외 | L4: 일반비용 | M4: 없음 | N4: E | O4: FALSE | P4: 제외 | Q4: FALSE | R4: 탄소 산정 대상 아님 | S4: 제외 케이스
A5: I004 | B5: C001 | C5: 45749 | D5: 구미가스 | E5: 공장 용접용 가스비 | F5: 320000 | G5: 32000 | H5: 352000 | K5: Scope 1 | L5: 고정연소 | M5: 가스종류 불명 | N5: C | O5: FALSE | P5: HITL | Q5: TRUE | R5: 가스 종류가 불명확해 사람검토 필요 | S5: 애매 케이스
A6: I005 | B6: C001 | C6: 45752 | D6: 대경오일 | E6: 납품차량 경유 주유 | F6: 410000 | G6: 41000 | H6: 451000 | I6: 310 | J6: L | K6: Scope 1 | L6: 이동연소 | M6: 경유 | N6: A | O6: FALSE | P6: 해당없음 | Q6: FALSE | R6: 납품차량+경유 명시 | S6: 명확 케이스
A7: I006 | B7: C001 | C7: 45757 | D7: 한국전력 | E7: 4월 전력 사용료 | F7: 1380000 | G7: 138000 | H7: 1518000 | I7: 4100 | J7: kWh | K7: Scope 2 | L7: 전력사용 | M7: 전기 | N7: A | O7: FALSE | P7: 해당없음 | Q7: FALSE | R7: 전력 사용료는 Scope 2 | S7: 명확 케이스
A8: I007 | B8: C001 | C8: 45760 | D8: 구미도시가스 | E8: 도시가스 요금 | F8: 220000 | G8: 22000 | H8: 242000 | I8: 180 | J8: m3 | K8: Scope 1 | L8: 고정연소 | M8: 도시가스 | N8: A | O8: FALSE | P8: 해당없음 | Q8: FALSE | R8: 도시가스 사용량 존재 | S8: 명확 케이스
A9: I008 | B9: C001 | C9: 45765 | D9: 성서산업상사 | E9: 공장 소모품 외 2종 | F9: 275000 | G9: 27500 | H9: 302500 | K9: 제외 | L9: 일반비용 | M9: 없음 | N9: E | O9: TRUE | P9: HITL | Q9: TRUE | R9: 품목이 모호하고 탄소 항목 여부 불확실 | S9: 애매/제외
A10: I009 | B10: C002 | C10: 45727 | D10: 경북LPG | E10: LPG 연료비 | F10: 180000 | G10: 18000 | H10: 198000 | I10: 95 | J10: kg | K10: Scope 1 | L10: 고정연소 | M10: LPG | N10: C | O10: FALSE | P10: HITL | Q10: TRUE | R10: LPG는 kg/L/Nm3 단위 확인 필요 | S10: 애매 케이스
A11: I010 | B11: C002 | C11: 45731 | D11: 한국전력 | E11: 전기료 | F11: 980000 | G11: 98000 | H11: 1078000 | I11: 2800 | J11: kWh | K11: Scope 2 | L11: 전력사용 | M11: 전기 | N11: A | O11: FALSE | P11: 해당없음 | Q11: FALSE | R11: 전기료 키워드 | S11: 명확 케이스
A12: I011 | B12: C002 | C12: 45739 | D12: 대경유류 | E12: 유류대금 | F12: 355000 | G12: 35500 | H12: 390500 | K12: Scope 1 | L12: 이동연소 | M12: 연료종류 불명 | N12: C | O12: FALSE | P12: HITL | Q12: TRUE | R12: 경유/휘발유 구분 불가 | S12: 애매 케이스
A13: I012 | B13: C002 | C13: 45748 | D13: 구미에너지 | E13: 경유 | F13: 785000 | G13: 78500 | H13: 863500 | I13: 600 | J13: L | K13: Scope 1 | L13: 이동연소 | M13: 경유 | N13: A | O13: FALSE | P13: 해당없음 | Q13: FALSE | R13: 경유 명시 | S13: 명확 케이스
A14: I013 | B14: C002 | C14: 45751 | D14: 동양가스 | E14: 산소/아르곤 가스 | F14: 440000 | G14: 44000 | H14: 484000 | K14: 검토 | L14: 산업가스 | M14: 산업가스 | N14: C | O14: TRUE | P14: HITL | Q14: TRUE | R14: 공정용 가스이나 배출계수 적용 여부 검토 필요 | S14: HITL
A15: I014 | B15: C002 | C15: 45756 | D15: 대구문구 | E15: 복사용지 및 토너 | F15: 210000 | G15: 21000 | H15: 231000 | K15: 제외 | L15: 일반비용 | M15: 없음 | N15: E | O15: FALSE | P15: 제외 | Q15: FALSE | R15: 일반 사무비용 | S15: 제외 케이스
A16: I015 | B16: C002 | C16: 45766 | D16: 한국전력 | E16: 공장 전기료 | F16: 1120000 | G16: 112000 | H16: 1232000 | I16: 3300 | J16: kWh | K16: Scope 2 | L16: 전력사용 | M16: 전기 | N16: A | O16: FALSE | P16: 해당없음 | Q16: FALSE | R16: 전기료는 Scope 2 | S16: 명확 케이스
A17: I016 | B17: C003 | C17: 45719 | D17: 구미도시가스 | E17: 보일러 도시가스 | F17: 360000 | G17: 36000 | H17: 396000 | I17: 295 | J17: m3 | K17: Scope 1 | L17: 고정연소 | M17: 도시가스 | N17: A | O17: FALSE | P17: 해당없음 | Q17: FALSE | R17: 보일러+도시가스 명시 | S17: 명확 케이스
A18: I017 | B18: C003 | C18: 45723 | D18: 한국전력 | E18: 전력 사용료 | F18: 1540000 | G18: 154000 | H18: 1694000 | I18: 4600 | J18: kWh | K18: Scope 2 | L18: 전력사용 | M18: 전기 | N18: A | O18: FALSE | P18: 해당없음 | Q18: FALSE | R18: 전력 사용료 | S18: 명확 케이스
A19: I018 | B19: C003 | C19: 45732 | D19: 포항오일 | E19: 지게차 경유 | F19: 520000 | G19: 52000 | H19: 572000 | I19: 400 | J19: L | K19: Scope 1 | L19: 이동연소 | M19: 경유 | N19: A | O19: FALSE | P19: 해당없음 | Q19: FALSE | R19: 지게차 경유 명시 | S19: 명확 케이스
A20: I019 | B20: C003 | C20: 45740 | D20: 구내식당 | E20: 야근 식대 | F20: 180000 | G20: 18000 | H20: 198000 | K20: 제외 | L20: 일반비용 | M20: 없음 | N20: E | O20: FALSE | P20: 제외 | Q20: FALSE | R20: 식대는 MVP 제외 | S20: 제외 케이스
A21: I020 | B21: C003 | C21: 45749 | D21: 경북LPG | E21: 공장 난방 LPG | F21: 260000 | G21: 26000 | H21: 286000 | I21: 135 | J21: kg | K21: Scope 1 | L21: 고정연소 | M21: LPG | N21: C | O21: FALSE | P21: HITL | Q21: TRUE | R21: LPG는 kg/L/Nm3 단위 확인 필요 | S21: 애매 케이스
A22: I021 | B22: C003 | C22: 45761 | D22: 대경정비 | E22: 지게차 정비비 | F22: 300000 | G22: 30000 | H22: 330000 | K22: 제외 | L22: 일반비용 | M22: 없음 | N22: E | O22: FALSE | P22: 제외 | Q22: FALSE | R22: 정비비는 연료 사용량 아님 | S22: 제외 케이스
A23: I022 | B23: C003 | C23: 45773 | D23: 한국전력 | E23: 전기요금 | F23: 1650000 | G23: 165000 | H23: 1815000 | I23: 5000 | J23: kWh | K23: Scope 2 | L23: 전력사용 | M23: 전기 | N23: A | O23: FALSE | P23: 해당없음 | Q23: FALSE | R23: 전기요금 키워드 | S23: 명확 케이스
A24: I023 | B24: C004 | C24: 45721 | D24: 구미에너지 | E24: 경유 외 1종 | F24: 432000 | G24: 43200 | H24: 475200 | I24: 330 | J24: L | K24: Scope 1 | L24: 이동연소 | M24: 경유 | N24: A | O24: TRUE | P24: 주품목 100% | Q24: FALSE | R24: 경유가 주품목으로 명확 | S24: 혼합 명확
A25: I024 | B25: C004 | C25: 45724 | D25: 한국전력 | E25: 3월 전기요금 | F25: 760000 | G25: 76000 | H25: 836000 | I25: 2200 | J25: kWh | K25: Scope 2 | L25: 전력사용 | M25: 전기 | N25: A | O25: FALSE | P25: 해당없음 | Q25: FALSE | R25: 전기요금 | S25: 명확 케이스
A26: I025 | B26: C004 | C26: 45735 | D26: 대구철물 | E26: 절삭유 및 소모품 | F26: 390000 | G26: 39000 | H26: 429000 | K26: 검토 | L26: 공정소모품 | M26: 없음 | N26: C | O26: TRUE | P26: HITL | Q26: TRUE | R26: 절삭유는 배출 산정 포함 여부 판단 필요 | S26: HITL
A27: I026 | B27: C004 | C27: 45748 | D27: 구미도시가스 | E27: 도시가스 | F27: 190000 | G27: 19000 | H27: 209000 | I27: 160 | J27: m3 | K27: Scope 1 | L27: 고정연소 | M27: 도시가스 | N27: A | O27: FALSE | P27: 해당없음 | Q27: FALSE | R27: 도시가스 명시 | S27: 명확 케이스
A28: I027 | B28: C004 | C28: 45758 | D28: 대구문구 | E28: 사무용 의자 | F28: 280000 | G28: 28000 | H28: 308000 | K28: 제외 | L28: 일반비용 | M28: 없음 | N28: E | O28: FALSE | P28: 제외 | Q28: FALSE | R28: 일반비용 | S28: 제외 케이스
A29: I028 | B29: C004 | C29: 45768 | D29: 한국전력 | E29: 공장 전력료 | F29: 830000 | G29: 83000 | H29: 913000 | I29: 2450 | J29: kWh | K29: Scope 2 | L29: 전력사용 | M29: 전기 | N29: A | O29: FALSE | P29: 해당없음 | Q29: FALSE | R29: 전력료는 Scope 2 | S29: 명확 케이스
A30: I029 | B30: C005 | C30: 45718 | D30: 포항오일 | E30: 화물차 경유 | F30: 910000 | G30: 91000 | H30: 1001000 | I30: 700 | J30: L | K30: Scope 1 | L30: 이동연소 | M30: 경유 | N30: A | O30: FALSE | P30: 해당없음 | Q30: FALSE | R30: 화물차 경유 명시 | S30: 명확 케이스
A31: I030 | B31: C005 | C31: 45729 | D31: 한국전력 | E31: 전기 사용료 | F31: 1950000 | G31: 195000 | H31: 2145000 | I31: 5800 | J31: kWh | K31: Scope 2 | L31: 전력사용 | M31: 전기 | N31: A | O31: FALSE | P31: 해당없음 | Q31: FALSE | R31: 전기 사용료 | S31: 명확 케이스
A32: I031 | B32: C005 | C32: 45737 | D32: 구미가스 | E32: 공장 가스비 | F32: 270000 | G32: 27000 | H32: 297000 | K32: Scope 1 | L32: 고정연소 | M32: 가스종류 불명 | N32: C | O32: FALSE | P32: HITL | Q32: TRUE | R32: 가스 종류 불명확 | S32: 애매 케이스
A33: I032 | B33: C005 | C33: 45750 | D33: 구내식당 | E33: 직원 식대 | F33: 420000 | G33: 42000 | H33: 462000 | K33: 제외 | L33: 일반비용 | M33: 없음 | N33: E | O33: FALSE | P33: 제외 | Q33: FALSE | R33: 식대 제외 | S33: 제외 케이스
A34: I033 | B34: C005 | C34: 45757 | D34: 한국전력 | E34: 전력 사용료 | F34: 2100000 | G34: 210000 | H34: 2310000 | I34: 6100 | J34: kWh | K34: Scope 2 | L34: 전력사용 | M34: 전기 | N34: A | O34: FALSE | P34: 해당없음 | Q34: FALSE | R34: 전력 사용료 | S34: 명확 케이스
A35: I034 | B35: C005 | C35: 45764 | D35: 대경오일 | E35: 휘발유 | F35: 120000 | G35: 12000 | H35: 132000 | I35: 70 | J35: L | K35: Scope 1 | L35: 이동연소 | M35: 휘발유 | N35: A | O35: FALSE | P35: 해당없음 | Q35: FALSE | R35: 휘발유 명시 | S35: 명확 케이스
A36: I035 | B36: C006 | C36: 45722 | D36: 한국전력 | E36: 전기요금 | F36: 640000 | G36: 64000 | H36: 704000 | I36: 1900 | J36: kWh | K36: Scope 2 | L36: 전력사용 | M36: 전기 | N36: A | O36: FALSE | P36: 해당없음 | Q36: FALSE | R36: 전기요금 | S36: 명확 케이스
A37: I036 | B37: C006 | C37: 45734 | D37: 경북LPG | E37: LPG | F37: 155000 | G37: 15500 | H37: 170500 | I37: 80 | J37: kg | K37: Scope 1 | L37: 고정연소 | M37: LPG | N37: C | O37: FALSE | P37: HITL | Q37: TRUE | R37: LPG는 kg/L/Nm3 단위 확인 필요 | S37: 애매 케이스
A38: I037 | B38: C006 | C38: 45745 | D38: 대경유류 | E38: 기타 유류대 | F38: 240000 | G38: 24000 | H38: 264000 | K38: Scope 1 | L38: 이동연소 | M38: 연료종류 불명 | N38: C | O38: FALSE | P38: HITL | Q38: TRUE | R38: 연료 종류가 불명확 | S38: 애매 케이스
A39: I038 | B39: C006 | C39: 45754 | D39: 대구문구 | E39: 문구류 | F39: 76000 | G39: 7600 | H39: 83600 | K39: 제외 | L39: 일반비용 | M39: 없음 | N39: E | O39: FALSE | P39: 제외 | Q39: FALSE | R39: 문구류 제외 | S39: 제외 케이스
A40: I039 | B40: C006 | C40: 45763 | D40: 한국전력 | E40: 공장 전기 사용료 | F40: 710000 | G40: 71000 | H40: 781000 | I40: 2100 | J40: kWh | K40: Scope 2 | L40: 전력사용 | M40: 전기 | N40: A | O40: FALSE | P40: 해당없음 | Q40: FALSE | R40: 전기 사용료 | S40: 명확 케이스
...

Sheet 분류_기준표_확장
A1: rule_id | B1: 우선순위 | C1: 대표키워드/문구 | D1: 포함 키워드 | E1: 제외/주의 키워드 | F1: 정답Scope | G1: 세부분류 | H1: 연료/항목 | I1: 자동처리 | J1: 사람검토필요 | K1: 혼합품목 플래그 | L1: 기본 데이터품질 | M1: 판단기준/근거 | N1: 예시 전표 문구
A2: R001 | B2: 1 | C2: 한국전력 | D2: 한국전력, 한전, 전기요금, 전력사용료, kWh | F2: Scope 2 | G2: 전력사용 | H2: 전기 | I2: 자동분류 | J2: FALSE | K2: FALSE | L2: A | M2: 전기 구매 사용은 Scope 2 | N2: 한국전력 전기요금 3월분
A3: R002 | B3: 1 | C3: 공장 전기 | D3: 전기료, 전기요금, 전력, 수전, kWh | E3: 배터리, 전기공사 | F3: Scope 2 | G3: 전력사용 | H3: 전기 | I3: 자동분류 | J3: FALSE | K3: FALSE | L3: A | M3: 전기 사용량이 명확하면 Scope 2 | N3: 공장 전력 사용료
A4: R003 | B4: 1 | C4: CNC 전기 | D4: CNC, 가공기, 설비, 전기료 | E4: 수리비, 설치비 | F4: Scope 2 | G4: 전력사용 | H4: 전기 | I4: 자동분류 | J4: FALSE | K4: FALSE | L4: B | M4: 설비 가동 전기 사용으로 판단 | N4: CNC 설비 전기료
A5: R004 | B5: 1 | C5: 공조 전기 | D5: 공조, 냉난방, 냉방, 전기료 | E5: 공조설비 구매 | F5: Scope 2 | G5: 전력사용 | H5: 전기 | I5: 자동분류 | J5: FALSE | K5: FALSE | L5: B | M5: 냉난방 전기 사용은 Scope 2 | N5: 공장 냉난방 전기료
A6: R005 | B6: 1 | C6: 지게차 경유 | D6: 지게차, 경유 | F6: Scope 1 | G6: 이동연소 | H6: 경유 | I6: 자동분류 | J6: FALSE | K6: TRUE | L6: A/B | M6: 지게차 이동장비 연료 | N6: 지게차 경유 외 1종
A7: R006 | B7: 1 | C7: 납품차량 경유 | D7: 납품차, 화물차, 차량, 경유, 주유 | F7: Scope 1 | G7: 이동연소 | H7: 경유 | I7: 자동분류 | J7: FALSE | K7: FALSE | L7: A/B | M7: 차량 연료는 이동연소 | N7: 납품 차량 경유 주유비
A8: R007 | B8: 1 | C8: 업무용 차량 휘발유 | D8: 업무용 차량, 승용차, 휘발유, 주유 | F8: Scope 1 | G8: 이동연소 | H8: 휘발유 | I8: 자동분류 | J8: FALSE | K8: FALSE | L8: A/B | M8: 차량 휘발유는 이동연소 | N8: 업무용 차량 휘발유
A9: R008 | B9: 1 | C9: 구내 운반차 연료 | D9: 구내 운반차, 운반차, 연료비 | E9: 경유/휘발유/LPG 불명 | F9: Scope 1 | G9: 이동연소 | H9: 유류 | I9: 검토후분류 | J9: TRUE | K9: FALSE | L9: C | M9: 연료 종류 확인 필요 | N9: 구내 운반차 연료비
A10: R009 | B10: 1 | C10: LPG 지게차 | D10: 지게차, LPG, 충전 | F10: Scope 1 | G10: 이동연소 | H10: LPG | I10: 검토후분류 | J10: TRUE | K10: FALSE | L10: C | M10: LPG 단위가 kg/L/Nm3인지 확인 필요 | N10: LPG 지게차 충전비
A11: R010 | B11: 2 | C11: 유류대금 | D11: 유류대, 주유대, 유류비 | E11: 경유/휘발유 불명 | F11: 검토 | G11: 연료종류 불명 | H11: 유류 | I11: 사람검토 | J11: TRUE | K11: FALSE | L11: C | M11: 연료 종류 불명확 | N11: 현장 유류대금
A12: R011 | B12: 1 | C12: 도시가스 | D12: 도시가스, 가스요금, 도시가스요금 | E12: LPG 도시가스 구분 필요 | F12: Scope 1 | G12: 고정연소 | H12: 도시가스(LNG) | I12: 자동분류 | J12: FALSE | K12: FALSE | L12: A/B | M12: 도시가스는 고정연소로 처리 | N12: 도시가스 3월분
A13: R012 | B13: 1 | C13: 보일러 도시가스 | D13: 보일러, 도시가스 | F13: Scope 1 | G13: 고정연소 | H13: 도시가스(LNG) | I13: 자동분류 | J13: FALSE | K13: FALSE | L13: A/B | M13: 고정 설비 연료 | N13: 공장 보일러용 도시가스
A14: R013 | B14: 1 | C14: 난방유 | D14: 난방유, 동절기 난방, 등유 | E14: 연료 종류 불명 | F14: Scope 1 | G14: 고정연소 | H14: 등유/난방유 | I14: 사람검토 | J14: TRUE | K14: FALSE | L14: C | M14: 난방유 종류 확인 필요 | N14: 동절기 난방유
A15: R014 | B15: 1 | C15: 공장 보일러 등유 | D15: 보일러, 등유 | F15: Scope 1 | G15: 고정연소 | H15: 등유 | I15: 자동분류 | J15: FALSE | K15: FALSE | L15: B | M15: 고정 설비에서 연료 연소 | N15: 공장 보일러 등유
A16: R015 | B16: 1 | C16: 열처리로 연료 | D16: 열처리로, 연료 | E16: 연료 종류 불명 | F16: Scope 1 | G16: 고정연소 | H16: 연료 불명 | I16: 사람검토 | J16: TRUE | K16: FALSE | L16: C | M16: 연료 종류 확인 필요 | N16: 열처리로 연료비
A17: R016 | B17: 1 | C17: 건조로 LPG | D17: 건조로, LPG | F17: Scope 1 | G17: 고정연소 | H17: LPG | I17: 사람검토 | J17: TRUE | K17: FALSE | L17: C | M17: LPG 사용 단위 확인 필요 | N17: 건조로 LPG 사용료
A18: R017 | B18: 1 | C18: 비상발전기 경유 | D18: 비상발전기, 발전기, 경유 | F18: Scope 1 | G18: 고정연소 | H18: 경유 | I18: 자동분류 | J18: FALSE | K18: FALSE | L18: A/B | M18: 고정 설비 연료 | N18: 비상발전기 경유
A19: R018 | B19: 2 | C19: 공장 가스비 | D19: 가스비, 공장가스 | E19: 도시가스/LPG/산업가스 불명 | F19: 검토 | G19: 가스종류 불명 | H19: 가스 | I19: 사람검토 | J19: TRUE | K19: FALSE | L19: C | M19: 가스 종류 확인 필요 | N19: 공장 가스비
A20: R019 | B20: 2 | C20: 용접용 가스비 | D20: 용접용 가스, 용접가스 | E20: 산소/아르곤/LPG/아세틸렌 불명 | F20: 검토 | G20: 산업가스/연료가스 불명 | H20: 가스 | I20: 사람검토 | J20: TRUE | K20: FALSE | L20: C | M20: 연료성 여부 확인 필요 | N20: 공장 용접용 가스비
A21: R020 | B21: 1 | C21: 산소 | D21: 산소, O2 | E21: 아세틸렌 등 혼합 제외 | F21: 제외 | G21: 산업가스/비연소 | H21: 산소 | I21: 자동제외 | J21: FALSE | K21: FALSE | L21: E | M21: 연료가 아니므로 Scope 1/2 산정 제외 | N21: 산소 가스 충전
A22: R021 | B22: 1 | C22: 아르곤 | D22: 아르곤, Ar | F22: 제외 | G22: 산업가스/비연소 | H22: 아르곤 | I22: 자동제외 | J22: FALSE | K22: FALSE | L22: E | M22: 비활성 보호가스, 직접 연소 배출 아님 | N22: 아르곤 가스
A23: R022 | B23: 1 | C23: 질소 | D23: 질소, N2 | F23: 제외 | G23: 산업가스/비연소 | H23: 질소 | I23: 자동제외 | J23: FALSE | K23: FALSE | L23: E | M23: 비연소 산업가스 | N23: 질소 가스 충전
A24: R023 | B24: 2 | C24: 산소·아르곤 외 | D24: 산소, 아르곤, 외 | E24: 외 항목 있음 | F24: 검토 | G24: 혼합 산업가스 | H24: 미정 | I24: 사람검토 | J24: TRUE | K24: TRUE | L24: C | M24: 외 항목에 연료성 가스 포함 가능 | N24: 산소·아르곤 가스 외
A25: R024 | B25: 1 | C25: 아세틸렌 | D25: 아세틸렌, 절단가스 | F25: Scope 1 | G25: 고정연소 | H25: 아세틸렌 | I25: 사람검토 | J25: TRUE | K25: FALSE | L25: C | M25: 연료성 가스 가능, 계수 확인 필요 | N25: 아세틸렌 절단가스
A26: R025 | B26: 1 | C26: LPG 절단가스 | D26: LPG, 절단가스 | F26: Scope 1 | G26: 고정연소 | H26: LPG | I26: 사람검토 | J26: TRUE | K26: FALSE | L26: C | M26: 연료성 가스이나 단위 확인 필요 | N26: LPG 절단가스
A27: R026 | B27: 2 | C27: 산업용 가스 | D27: 산업용 가스, 공업용 가스 | E27: 종류 불명 | F27: 검토 | G27: 산업가스 불명 | H27: 미정 | I27: 사람검토 | J27: TRUE | K27: FALSE | L27: C | M27: 가스 종류별로 처리 다름 | N27: 산업용 가스 구입
A28: R027 | B28: 2 | C28: 가스 외 1종 | D28: 가스, 외 1종 | E28: 혼합품목 | F28: 검토 | G28: 혼합품목 | H28: 미정 | I28: 사람검토 | J28: TRUE | K28: TRUE | L28: C | M28: 혼합품목이고 연료성 여부 불명확 | N28: 용접용 가스 외 1종
A29: R028 | B29: 2 | C29: 경유 외 1종 | D29: 경유, 외 1종 | E29: 주 품목 명확 | F29: Scope 1 | G29: 이동연소 | H29: 경유 | I29: 자동분류 | J29: FALSE | K29: TRUE | L29: B | M29: MVP는 주 품목 100% 귀속 | N29: 지게차 경유 외 1종
A30: R029 | B30: 2 | C30: 전기요금 외 | D30: 전기요금, 외 | E30: 주 품목 명확 | F30: Scope 2 | G30: 전력사용 | H30: 전기 | I30: 자동분류 | J30: FALSE | K30: TRUE | L30: B | M30: 주 품목 전기요금 100% 귀속 | N30: 공장 전기요금 외
A31: R030 | B31: 2 | C31: 설비 전기공사 | D31: 전기공사, 배선, 수전설비 | E31: 사용량 아님 | F31: 제외 | G31: 설비/공사비 | H31: 없음 | I31: 자동제외 | J31: FALSE | K31: FALSE | L31: E | M31: 전기 사용량이 아니라 공사비 | N31: 수전설비 전기공사
A32: R031 | B32: 2 | C32: 고효율 설비 | D32: 고효율, 인버터, 공조설비, 설비구매 | F32: 제외/참고 | G32: 감축투자 후보 | H32: 설비투자 | I32: 참고분류 | J32: TRUE | K32: FALSE | L32: E | M32: 배출량 계산 대상은 아니나 금융추천 후보 | N32: 고효율 공조설비 구매
A33: R032 | B33: 2 | C33: CNC 장비 구매 | D33: CNC, 장비구매, 설비도입 | E33: 전기료 아님 | F33: 제외/참고 | G33: 설비투자 | H33: 없음 | I33: 참고분류 | J33: FALSE | K33: FALSE | L33: E | M33: 구매비는 Scope1/2 활동자료 아님 | N33: CNC 장비 구매
A34: R033 | B34: 2 | C34: 프레스기 수리 | D34: 수리비, 프레스기, 정비 | F34: 제외 | G34: 수리비 | H34: 없음 | I34: 자동제외 | J34: FALSE | K34: FALSE | L34: E | M34: 직접 에너지 사용 아님 | N34: 프레스기 수리비
A35: R034 | B35: 2 | C35: 공구·소모품 | D35: 공구, 소모품, 절삭공구 | F35: 제외 | G35: 일반비용 | H35: 없음 | I35: 자동제외 | J35: FALSE | K35: FALSE | L35: E | M35: MVP Scope1/2 제외 | N35: 절삭공구 구매
A36: R035 | B36: 2 | C36: 사무용품 | D36: 사무용품, 문구, 복사용지 | F36: 제외 | G36: 일반비용 | H36: 없음 | I36: 자동제외 | J36: FALSE | K36: FALSE | L36: E | M36: MVP Scope1/2 제외 | N36: 사무용품 구입
A37: R036 | B37: 2 | C37: 식대 | D37: 식대, 간식, 회식 | F37: 제외 | G37: 일반비용 | H37: 없음 | I37: 자동제외 | J37: FALSE | K37: FALSE | L37: E | M37: 탄소 계산 대상 아님 | N37: 직원 식대
A38: R037 | B38: 2 | C38: 금속 원재료 | D38: 철판, 알루미늄, 스테인리스, 원재료 | F38: 제외/Scope3 후보 | G38: 원재료 | H38: 금속 | I38: 참고분류 | J38: TRUE | K38: FALSE | L38: E | M38: MVP는 Scope1/2만 산정 | N38: 금속 원재료 매입
A39: R038 | B39: 2 | C39: 도금/표면처리 외주 | D39: 도금, 표면처리, 외주가공 | F39: 제외/Scope3 후보 | G39: 외주가공 | H39: 없음 | I39: 참고분류 | J39: TRUE | K39: FALSE | L39: E | M39: 외주 공정은 MVP 제외 | N39: 부품 표면처리 외주비
A40: R039 | B40: 2 | C40: 폐기물 처리 | D40: 폐기물, 폐수, 처리비 | F40: 제외/Scope3 후보 | G40: 폐기물 | H40: 없음 | I40: 참고분류 | J40: TRUE | K40: FALSE | L40: E | M40: MVP Scope1/2 제외 | N40: 폐기물 처리비
...

Sheet 배출계수
A1: 연료/에너지 | B1: Scope | C1: 단위 | D1: 배출계수_kgCO2e_per_unit | E1: 월별_환산단가_공급가액 | F1: 단가단위 | G1: 출처URL | H1: 비고
A2: 경유 | B2: Scope 1 | C2: L | D2: 2.616 | E2: 1308 | F2: 원/L | G2: https://www.gir.go.kr | H2: 에너지법 시행규칙 별표 ‘연료별 국가 고유 발열량’의 경유 순발열량 35.3 MJ/L와 이산화탄소 배출계수표의 경유 74,100 kgCO₂/TJ를 적용하여 환산
A3: 휘발유 | B3: Scope 1 | C3: L | D3: 2.221 | E3: 1580 | F3: 원/L | G3: https://www.gir.go.kr | H3: 에너지법 시행규칙 별표 ‘연료별 국가 고유 발열량’의 휘발유 순발열량 30.3 MJ/L와 이산화탄소 배출계수표의 휘발유 73,300 kgCO₂/TJ를 적용하여 환산
A4: 도시가스 | B4: Scope 1 | C4: m3 | D4: 2.21 | E4: 1220 | F4: 원/m3 | G4: https://www.gir.go.kr | H4: 에너지법 시행규칙 별표 ‘연료별 국가 고유 발열량’의 도시가스(LNG) 순발열량 39.4 MJ/Nm³와 이산화탄소 배출계수표의 LNG 56,100 kgCO₂/TJ를 적용하여 에너지법 시행규칙 별표 ‘연료별 국가 고유 발열량’의 도시가스(LNG) 순발열량 39.4 MJ/Nm³와 이산화탄소 배출계수표의 LNG 56,100 kgCO₂/TJ를 적용하여 환산
A5: LPG | B5: Scope 1 | C5: kg | D5: 3.722 | E5: 1700 | F5: 원/kg | G5: https://www.gir.go.kr | H5: 에너지법 시행규칙 별표 ‘연료별 국가 고유 발열량’의 도시가스(LPG) 순발열량 57.7 MJ/Nm³와 이산화탄소 배출계수표의 LPG 64,500 kgCO₂/TJ를 적용하여 환산
A6: 전기 | B6: Scope 2 | C6: kWh | D6: 0.4541 | E6: 160 | F6: 원/kWh | G6: https://www.kpx.or.kr | H6: 2024 승인 전력배출계수 소비단 CO₂eq 배출계수 사용. 원자료 단위 0.4541 tCO₂eq/MWh를 kgCO₂eq/kWh로 환산 시 동일값 적용
A7: 가스종류 불명 | B7: Scope 1 | H7: HITL 필요
A8: 연료종류 불명 | B8: Scope 1 | H8: HITL 필요
A9: 없음 | B9: 제외 | D9: 0 | H9: 산정 제외

Sheet 기대_결과
A1: 전표ID | B1: 품목명 | C1: 결과Scope | D1: 결과연료 | E1: 공급가액 | F1: 활동량 | G1: 단위 | H1: 배출계수 | I1: 예상배출량_kgCO2e | J1: 사람검토필요 | K1: 결과근거 | L1: 뱉어야 하는 핵심 결과
A2: =전표_샘플!A2 -> I001 | B2: =전표_샘플!E2 -> 지게차 경유 외 1종 | C2: =전표_샘플!K2 -> Scope 1 | D2: =전표_샘플!M2 -> 경유 | E2: =전표_샘플!F2 -> 654000 | F2: =전표_샘플!I2 -> 500 | G2: =전표_샘플!J2 -> L | H2: =IFERROR(VLOOKUP(D2,배출계수!$A:$D,4,FALSE),"") -> 2.616 | I2: =IF(OR(F2="",H2=""),"",F2*H2) -> 1308 | J2: =전표_샘플!Q2 -> FALSE | K2: =전표_샘플!R2 -> 지게차+경유가 명시되어 직접배출 | L2: =IF(J2="TRUE","사람검토필요로 넘김",IF(C2="제외","탄소 산정 제외",C2&" / "&D2&" / "&TEXT(I2,"0.0")&" kgCO2e")) -> Scope 1 / 경유 / 1308.0 kgCO2e
A3: =전표_샘플!A3 -> I002 | B3: =전표_샘플!E3 -> 공장 전기요금 | C3: =전표_샘플!K3 -> Scope 2 | D3: =전표_샘플!M3 -> 전기 | E3: =전표_샘플!F3 -> 1200000 | F3: =전표_샘플!I3 -> 3500 | G3: =전표_샘플!J3 -> kWh | H3: =IFERROR(VLOOKUP(D3,배출계수!$A:$D,4,FALSE),"") -> 0.4541 | I3: =IF(OR(F3="",H3=""),"",F3*H3) -> 1589.35 | J3: =전표_샘플!Q3 -> FALSE | K3: =전표_샘플!R3 -> 한전 전기요금은 Scope 2 | L3: =IF(J3="TRUE","사람검토필요로 넘김",IF(C3="제외","탄소 산정 제외",C3&" / "&D3&" / "&TEXT(I3,"0.0")&" kgCO2e")) -> Scope 2 / 전기 / 1589.4 kgCO2e
A4: =전표_샘플!A4 -> I003 | B4: =전표_샘플!E4 -> 사무용품 구입 | C4: =전표_샘플!K4 -> 제외 | D4: =전표_샘플!M4 -> 없음 | E4: =전표_샘플!F4 -> 150000 | F4: =전표_샘플!I4 -> 0 | G4: =전표_샘플!J4 -> 0 | H4: =IFERROR(VLOOKUP(D4,배출계수!$A:$D,4,FALSE),"") -> 0 | I4: =IF(OR(F4="",H4=""),"",F4*H4) -> 0 | J4: =전표_샘플!Q4 -> FALSE | K4: =전표_샘플!R4 -> 탄소 산정 대상 아님 | L4: =IF(J4="TRUE","사람검토필요로 넘김",IF(C4="제외","탄소 산정 제외",C4&" / "&D4&" / "&TEXT(I4,"0.0")&" kgCO2e")) -> 탄소 산정 제외
A5: =전표_샘플!A5 -> I004 | B5: =전표_샘플!E5 -> 공장 용접용 가스비 | C5: =전표_샘플!K5 -> Scope 1 | D5: =전표_샘플!M5 -> 가스종류 불명 | E5: =전표_샘플!F5 -> 320000 | F5: =전표_샘플!I5 -> 0 | G5: =전표_샘플!J5 -> 0 | H5: =IFERROR(VLOOKUP(D5,배출계수!$A:$D,4,FALSE),"") -> 0 | I5: =IF(OR(F5="",H5=""),"",F5*H5) -> 0 | J5: =전표_샘플!Q5 -> TRUE | K5: =전표_샘플!R5 -> 가스 종류가 불명확해 사람검토 필요 | L5: =IF(J5="TRUE","사람검토필요로 넘김",IF(C5="제외","탄소 산정 제외",C5&" / "&D5&" / "&TEXT(I5,"0.0")&" kgCO2e")) -> 사람검토필요로 넘김
A6: =전표_샘플!A6 -> I005 | B6: =전표_샘플!E6 -> 납품차량 경유 주유 | C6: =전표_샘플!K6 -> Scope 1 | D6: =전표_샘플!M6 -> 경유 | E6: =전표_샘플!F6 -> 410000 | F6: =전표_샘플!I6 -> 310 | G6: =전표_샘플!J6 -> L | H6: =IFERROR(VLOOKUP(D6,배출계수!$A:$D,4,FALSE),"") -> 2.616 | I6: =IF(OR(F6="",H6=""),"",F6*H6) -> 810.96 | J6: =전표_샘플!Q6 -> FALSE | K6: =전표_샘플!R6 -> 납품차량+경유 명시 | L6: =IF(J6="TRUE","사람검토필요로 넘김",IF(C6="제외","탄소 산정 제외",C6&" / "&D6&" / "&TEXT(I6,"0.0")&" kgCO2e")) -> Scope 1 / 경유 / 811.0 kgCO2e
A7: =전표_샘플!A7 -> I006 | B7: =전표_샘플!E7 -> 4월 전력 사용료 | C7: =전표_샘플!K7 -> Scope 2 | D7: =전표_샘플!M7 -> 전기 | E7: =전표_샘플!F7 -> 1380000 | F7: =전표_샘플!I7 -> 4100 | G7: =전표_샘플!J7 -> kWh | H7: =IFERROR(VLOOKUP(D7,배출계수!$A:$D,4,FALSE),"") -> 0.4541 | I7: =IF(OR(F7="",H7=""),"",F7*H7) -> 1861.81 | J7: =전표_샘플!Q7 -> FALSE | K7: =전표_샘플!R7 -> 전력 사용료는 Scope 2 | L7: =IF(J7="TRUE","사람검토필요로 넘김",IF(C7="제외","탄소 산정 제외",C7&" / "&D7&" / "&TEXT(I7,"0.0")&" kgCO2e")) -> Scope 2 / 전기 / 1861.8 kgCO2e
A8: =전표_샘플!A8 -> I007 | B8: =전표_샘플!E8 -> 도시가스 요금 | C8: =전표_샘플!K8 -> Scope 1 | D8: =전표_샘플!M8 -> 도시가스 | E8: =전표_샘플!F8 -> 220000 | F8: =전표_샘플!I8 -> 180 | G8: =전표_샘플!J8 -> m3 | H8: =IFERROR(VLOOKUP(D8,배출계수!$A:$D,4,FALSE),"") -> 2.21 | I8: =IF(OR(F8="",H8=""),"",F8*H8) -> 397.8 | J8: =전표_샘플!Q8 -> FALSE | K8: =전표_샘플!R8 -> 도시가스 사용량 존재 | L8: =IF(J8="TRUE","사람검토필요로 넘김",IF(C8="제외","탄소 산정 제외",C8&" / "&D8&" / "&TEXT(I8,"0.0")&" kgCO2e")) -> Scope 1 / 도시가스 / 397.8 kgCO2e
A9: =전표_샘플!A9 -> I008 | B9: =전표_샘플!E9 -> 공장 소모품 외 2종 | C9: =전표_샘플!K9 -> 제외 | D9: =전표_샘플!M9 -> 없음 | E9: =전표_샘플!F9 -> 275000 | F9: =전표_샘플!I9 -> 0 | G9: =전표_샘플!J9 -> 0 | H9: =IFERROR(VLOOKUP(D9,배출계수!$A:$D,4,FALSE),"") -> 0 | I9: =IF(OR(F9="",H9=""),"",F9*H9) -> 0 | J9: =전표_샘플!Q9 -> TRUE | K9: =전표_샘플!R9 -> 품목이 모호하고 탄소 항목 여부 불확실 | L9: =IF(J9="TRUE","사람검토필요로 넘김",IF(C9="제외","탄소 산정 제외",C9&" / "&D9&" / "&TEXT(I9,"0.0")&" kgCO2e")) -> 사람검토필요로 넘김
A10: =전표_샘플!A10 -> I009 | B10: =전표_샘플!E10 -> LPG 연료비 | C10: =전표_샘플!K10 -> Scope 1 | D10: =전표_샘플!M10 -> LPG | E10: =전표_샘플!F10 -> 180000 | F10: =전표_샘플!I10 -> 95 | G10: =전표_샘플!J10 -> kg | H10: =IFERROR(VLOOKUP(D10,배출계수!$A:$D,4,FALSE),"") -> 3.722 | I10: =IF(OR(F10="",H10=""),"",F10*H10) -> 353.59 | J10: =전표_샘플!Q10 -> TRUE | K10: =전표_샘플!R10 -> LPG는 kg/L/Nm3 단위 확인 필요 | L10: =IF(J10="TRUE","사람검토필요로 넘김",IF(C10="제외","탄소 산정 제외",C10&" / "&D10&" / "&TEXT(I10,"0.0")&" kgCO2e")) -> 사람검토필요로 넘김
A11: =전표_샘플!A11 -> I010 | B11: =전표_샘플!E11 -> 전기료 | C11: =전표_샘플!K11 -> Scope 2 | D11: =전표_샘플!M11 -> 전기 | E11: =전표_샘플!F11 -> 980000 | F11: =전표_샘플!I11 -> 2800 | G11: =전표_샘플!J11 -> kWh | H11: =IFERROR(VLOOKUP(D11,배출계수!$A:$D,4,FALSE),"") -> 0.4541 | I11: =IF(OR(F11="",H11=""),"",F11*H11) -> 1271.48 | J11: =전표_샘플!Q11 -> FALSE | K11: =전표_샘플!R11 -> 전기료 키워드 | L11: =IF(J11="TRUE","사람검토필요로 넘김",IF(C11="제외","탄소 산정 제외",C11&" / "&D11&" / "&TEXT(I11,"0.0")&" kgCO2e")) -> Scope 2 / 전기 / 1271.5 kgCO2e
A12: =전표_샘플!A12 -> I011 | B12: =전표_샘플!E12 -> 유류대금 | C12: =전표_샘플!K12 -> Scope 1 | D12: =전표_샘플!M12 -> 연료종류 불명 | E12: =전표_샘플!F12 -> 355000 | F12: =전표_샘플!I12 -> 0 | G12: =전표_샘플!J12 -> 0 | H12: =IFERROR(VLOOKUP(D12,배출계수!$A:$D,4,FALSE),"") -> 0 | I12: =IF(OR(F12="",H12=""),"",F12*H12) -> 0 | J12: =전표_샘플!Q12 -> TRUE | K12: =전표_샘플!R12 -> 경유/휘발유 구분 불가 | L12: =IF(J12="TRUE","사람검토필요로 넘김",IF(C12="제외","탄소 산정 제외",C12&" / "&D12&" / "&TEXT(I12,"0.0")&" kgCO2e")) -> 사람검토필요로 넘김
A13: =전표_샘플!A13 -> I012 | B13: =전표_샘플!E13 -> 경유 | C13: =전표_샘플!K13 -> Scope 1 | D13: =전표_샘플!M13 -> 경유 | E13: =전표_샘플!F13 -> 785000 | F13: =전표_샘플!I13 -> 600 | G13: =전표_샘플!J13 -> L | H13: =IFERROR(VLOOKUP(D13,배출계수!$A:$D,4,FALSE),"") -> 2.616 | I13: =IF(OR(F13="",H13=""),"",F13*H13) -> 1569.6 | J13: =전표_샘플!Q13 -> FALSE | K13: =전표_샘플!R13 -> 경유 명시 | L13: =IF(J13="TRUE","사람검토필요로 넘김",IF(C13="제외","탄소 산정 제외",C13&" / "&D13&" / "&TEXT(I13,"0.0")&" kgCO2e")) -> Scope 1 / 경유 / 1569.6 kgCO2e
... A41: =전표_샘플!A41 -> I040 | B41: =전표_샘플!E41 -> 도시가스 요금 | C41: =전표_샘플!K41 -> Scope 1 | D41: =전표_샘플!M41 -> 도시가스 | E41: =전표_샘플!F41 -> 115000 | F41: =전표_샘플!I41 -> 95 | G41: =전표_샘플!J41 -> m3 | H41: =IFERROR(VLOOKUP(D41,배출계수!$A:$D,4,FALSE),"") -> 2.21 | I41: =IF(OR(F41="",H41=""),"",F41*H41) -> 209.95 | J41: =전표_샘플!Q41 -> FALSE | K41: =전표_샘플!R41 -> 도시가스 사용량 | L41: =IF(J41="TRUE","사람검토필요로 넘김",IF(C41="제외","탄소 산정 제외",C41&" / "&D41&" / "&TEXT(I41,"0.0")&" kgCO2e")) -> Scope 1 / 도시가스 / 210.0 kgCO2e
A42: I041 | B42: 경유 주유비 | C42: Scope 1 | D42: 경유 | E42: 280000 | F42: 198.07 | G42: L | H42: 2.616 | I42: 518.14 | J42: FALSE | K42: 경유는 명시되어 있으나 수량이 없어 월별단가로 활동량 추정 | L42: Scope 1 / 경유 / 월별단가 환산 / 518.1 kgCO2e

Sheet 월별단가
A1: 연료 | B1: 연 | C1: 월 | D1: 단가 | E1: 단가단위 | F1: 활동량단위 | G1: 부가세포함여부 | H1: 확정여부 | I1: 출처/비고
A2: 휘발유 | B2: 2025 | C2: 1 | D2: 1553.9 | E2: 원/L | F2: L | G2: 부가세제외 | H2: 공식환산 | I2: 업로드 파일 '주유소_평균판매가격_제품별.csv'의 보통휘발유 월평균 판매가격 1709.29원/L ÷ 1.1
A3: 휘발유 | B3: 2025 | C3: 2 | D3: 1571.15 | E3: 원/L | F3: L | G3: 부가세제외 | H3: 공식환산 | I3: 업로드 파일 '주유소_평균판매가격_제품별.csv'의 보통휘발유 월평균 판매가격 1728.26원/L ÷ 1.1
A4: 휘발유 | B4: 2025 | C4: 3 | D4: 1535.39 | E4: 원/L | F4: L | G4: 부가세제외 | H4: 공식환산 | I4: 업로드 파일 '주유소_평균판매가격_제품별.csv'의 보통휘발유 월평균 판매가격 1688.93원/L ÷ 1.1
A5: 휘발유 | B5: 2025 | C5: 4 | D5: 1496.99 | E5: 원/L | F5: L | G5: 부가세제외 | H5: 공식환산 | I5: 업로드 파일 '주유소_평균판매가격_제품별.csv'의 보통휘발유 월평균 판매가격 1646.69원/L ÷ 1.1
A6: 휘발유 | B6: 2025 | C6: 5 | D6: 1487.68 | E6: 원/L | F6: L | G6: 부가세제외 | H6: 공식환산 | I6: 업로드 파일 '주유소_평균판매가격_제품별.csv'의 보통휘발유 월평균 판매가격 1636.45원/L ÷ 1.1
A7: 휘발유 | B7: 2025 | C7: 6 | D7: 1492.8 | E7: 원/L | F7: L | G7: 부가세제외 | H7: 공식환산 | I7: 업로드 파일 '주유소_평균판매가격_제품별.csv'의 보통휘발유 월평균 판매가격 1642.08원/L ÷ 1.1
A8: 휘발유 | B8: 2025 | C8: 7 | D8: 1515.98 | E8: 원/L | F8: L | G8: 부가세제외 | H8: 공식환산 | I8: 업로드 파일 '주유소_평균판매가격_제품별.csv'의 보통휘발유 월평균 판매가격 1667.58원/L ÷ 1.1
A9: 휘발유 | B9: 2025 | C9: 8 | D9: 1514.46 | E9: 원/L | F9: L | G9: 부가세제외 | H9: 공식환산 | I9: 업로드 파일 '주유소_평균판매가격_제품별.csv'의 보통휘발유 월평균 판매가격 1665.91원/L ÷ 1.1
A10: 휘발유 | B10: 2025 | C10: 9 | D10: 1508.98 | E10: 원/L | F10: L | G10: 부가세제외 | H10: 공식환산 | I10: 업로드 파일 '주유소_평균판매가격_제품별.csv'의 보통휘발유 월평균 판매가격 1659.88원/L ÷ 1.1
A11: 휘발유 | B11: 2025 | C11: 10 | D11: 1512.02 | E11: 원/L | F11: L | G11: 부가세제외 | H11: 공식환산 | I11: 업로드 파일 '주유소_평균판매가격_제품별.csv'의 보통휘발유 월평균 판매가격 1663.22원/L ÷ 1.1
A12: 휘발유 | B12: 2025 | C12: 11 | D12: 1561.95 | E12: 원/L | F12: L | G12: 부가세제외 | H12: 공식환산 | I12: 업로드 파일 '주유소_평균판매가격_제품별.csv'의 보통휘발유 월평균 판매가격 1718.14원/L ÷ 1.1
A13: 휘발유 | B13: 2025 | C13: 12 | D13: 1582 | E13: 원/L | F13: L | G13: 부가세제외 | H13: 공식환산 | I13: 업로드 파일 '주유소_평균판매가격_제품별.csv'의 보통휘발유 월평균 판매가격 1740.20원/L ÷ 1.1
... A49: LPG(부탄) | B49: 2025 | C49: 12 | D49: 1421.04 | E49: 원/kg | F49: kg | G49: 부가세제외 | H49: 공식환산 | I49: 업로드 파일 'LPG충전소_제품별_평균판매가격.csv'의 일반부탄 월평균 판매가격 1563.14원/kg ÷ 1.1
A50: 전기 | B50: 2025 | C50: 1 | E50: 원/kWh | F50: kWh | G50: 확인필요 | H50: 사용량우선 | I50: 전기는 실제 고지서의 kWh 사용량을 우선 사용. 금액만 있는 경우에는 사람검토 또는 보조단가 필요
A51: 전기 | B51: 2025 | C51: 2 | E51: 원/kWh | F51: kWh | G51: 확인필요 | H51: 사용량우선 | I51: 전기는 실제 고지서의 kWh 사용량을 우선 사용. 금액만 있는 경우에는 사람검토 또는 보조단가 필요
A52: 전기 | B52: 2025 | C52: 3 | E52: 원/kWh | F52: kWh | G52: 확인필요 | H52: 사용량우선 | I52: 전기는 실제 고지서의 kWh 사용량을 우선 사용. 금액만 있는 경우에는 사람검토 또는 보조단가 필요
A53: 전기 | B53: 2025 | C53: 4 | E53: 원/kWh | F53: kWh | G53: 확인필요 | H53: 사용량우선 | I53: 전기는 실제 고지서의 kWh 사용량을 우선 사용. 금액만 있는 경우에는 사람검토 또는 보조단가 필요
A54: 전기 | B54: 2025 | C54: 5 | E54: 원/kWh | F54: kWh | G54: 확인필요 | H54: 사용량우선 | I54: 전기는 실제 고지서의 kWh 사용량을 우선 사용. 금액만 있는 경우에는 사람검토 또는 보조단가 필요
A55: 전기 | B55: 2025 | C55: 6 | E55: 원/kWh | F55: kWh | G55: 확인필요 | H55: 사용량우선 | I55: 전기는 실제 고지서의 kWh 사용량을 우선 사용. 금액만 있는 경우에는 사람검토 또는 보조단가 필요
A56: 전기 | B56: 2025 | C56: 7 | E56: 원/kWh | F56: kWh | G56: 확인필요 | H56: 사용량우선 | I56: 전기는 실제 고지서의 kWh 사용량을 우선 사용. 금액만 있는 경우에는 사람검토 또는 보조단가 필요
A57: 전기 | B57: 2025 | C57: 8 | E57: 원/kWh | F57: kWh | G57: 확인필요 | H57: 사용량우선 | I57: 전기는 실제 고지서의 kWh 사용량을 우선 사용. 금액만 있는 경우에는 사람검토 또는 보조단가 필요
A58: 전기 | B58: 2025 | C58: 9 | E58: 원/kWh | F58: kWh | G58: 확인필요 | H58: 사용량우선 | I58: 전기는 실제 고지서의 kWh 사용량을 우선 사용. 금액만 있는 경우에는 사람검토 또는 보조단가 필요
A59: 전기 | B59: 2025 | C59: 10 | E59: 원/kWh | F59: kWh | G59: 확인필요 | H59: 사용량우선 | I59: 전기는 실제 고지서의 kWh 사용량을 우선 사용. 금액만 있는 경우에는 사람검토 또는 보조단가 필요
A60: 전기 | B60: 2025 | C60: 11 | E60: 원/kWh | F60: kWh | G60: 확인필요 | H60: 사용량우선 | I60: 전기는 실제 고지서의 kWh 사용량을 우선 사용. 금액만 있는 경우에는 사람검토 또는 보조단가 필요
A61: 도시가스 | B61: 2025 | C61: 1 | E61: 원/m3 | F61: m3 | G61: 확인필요 | H61: 사용량우선 | I61: 도시가스는 지역·용도별 요금 차이가 있어 실제 고지서의 m3 사용량을 우선 사용
... A72: 도시가스 | B72: 2025 | C72: 12 | E72: 원/m3 | F72: m3 | G72: 확인필요 | H72: 사용량우선 | I72: 도시가스는 지역·용도별 요금 차이가 있어 실제 고지서의 m3 사용량을 우선 사용
